Workbook
Name __bookmark_1: CH_CA Charge [1]Master!$A$2:$AT$12030

Sheet Top 50 List
A1: Count | B1: Description | C1: Procedure Type
A2: 210 | B2: X-Ray, Chest, two views | C2: Radiology - X-Ray
A3: 201 | B3: Electrocardiogram | C3: Medicine - Cardiovascular
A4: 167 | B4: Comprehensive Metabolic Panel | C4: Laboratory
A5: 148 | B5: Complete Blood Count, with differential | C5: Laboratory
A6: 142 | B6: Basic Metabolic Panel | C6: Laboratory
A7: 134 | B7: X-Ray, Chest, one view | C7: Radiology - X-Ray
A8: 127 | B8: Prothrombin Time | C8: Laboratory
A9: 127 | B9: Physical Therapy - Therapeutic Exercise | C9: Medicine - Physical Medicine
A10: 121 | B10: Mammography, Screening, Bilateral | C10: Radiology
A11: 119 | B11: Colonoscopy | C11: Surgery
A12: 116 | B12: CT Scan, Head or Brain, without contrast | C12: Radiology - CT Scan
A13: 114 | B13: Urinalysis | C13: Laboratory
... A51: 34 | B51: Culture, Urine | C51: Laboratory

Sheet AB 1045 Form
A1: Hospital Name: Chinese Hospital
A2: HCAI Facility No: 106382715
A3: Effective Date of Charges: 06/01/2024
A4: In response to requests from hospitals and the public, HCAI has developed this form to assist hospitals in collecting and submitting the average charge for 25 common outpatient procedures performed by hospitals, as required by AB 1045 (Chapter 532, Statutes of 2005). Use of the HCAI form is voluntary, but highly encouraged, as it allows hospitals to report and the public to compare uniform information regarding common outpatient procedures.
A5: Evaluation & Management Services (CPT Codes 99201-99499) | B5: 2024 CPT Code | C5: Average Charge
A6: Emergency Room Visit (straightforward) | B6: 99282 | C6: 695
A7: Emergency Room Visit (low level) | B7: 99283 | C7: 1300
A8: Emergency Room Visit (moderate level) | B8: 99284 | C8: 2043
A9: Emergency Room Visit (high level) | B9: 99285 | C9: 2928
A10: Outpatient Visit, established patient, 20+ minutes | B10: 99213 | C10: 171
A11: Laboratory & Pathology Services (CPT Codes 80047-89398) | B11: 2024 CPT Code | C11: Average Charge
A12: Basic Metabolic Panel | B12: 80048 | C12: 120
A13: Blood Gas Analysis, including 02 saturation | B13: 82805
A14: Complete Blood Count, automated | B14: 85027 | C14: 194
A15: Complete Blood Count, with differential WBC, automated | B15: 85025 | C15: 194
A16: Comprehensive Metabolic Panel | B16: 80053 | C16: 344
A17: Creatine Kinase (CK), (CPK), Total | B17: 82550 | C17: 227
A18: Lipid Panel | B18: 80061 | C18: 218
A19: Partial Thromboplastin Time | B19: 85730 | C19: 235
A20: Prothrombin Time | B20: 85610 | C20: 213
A21: Thyroid Stimulating Hormone | B21: 84443 | C21: 308
A22: Troponin, Quantitative | B22: 84484 | C22: 204
A23: Urinalysis, without microscopy | B23: 81002 or 81003 | C23: 26
A24: Urinalysis, with microscopy | B24: 81000 or 81001 | C24: 166
A25: Radiology Services (CPT Codes 70010-79999) | B25: 2024 CPT Code | C25: Average Charge
A26: CT Scan, Abdomen, with contrast | B26: 74160 | C26: 3275
A27: CT Scan, Head or Brain, without contrast | B27: 70450 | C27: 2480
A28: CT Scan, Pelvis, with contrast | B28: 72193
A29: Mammography, Screening, Bilateral | B29: 77067 | C29: 516
A30: MRI, Brain, without contrast, followed by contrast | B30: 70553 | C30: 6300
A31: Ultrasound, Abdomen, Complete | B31: 76700 | C31: 2103
A32: Ultrasound, OB, 14 weeks or more, transabdominal | B32: 76805
A33: X-Ray, Lower Back, minimum four views | B33: 72110 | C33: 974
A34: X-Ray, Chest, two views | B34: 71046 | C34: 566
A35: Medicine Services (CPT Codes 90281-99607) | B35: 2024 CPT Code | C35: Average Charge
A36: Cardiac Catheterization, Left Heart, percutaneous | B36: 93452
A37: Echocardiography, Transthoracic, complete, without Doppler | B37: 93307 | C37: 591
A38: Electrocardiogram, routine, with interpretation and report | B38: 93000 | C38: 79
A39: Inhalation Treatment, pressurized or nonpressurized | B39: 94640 | C39: 1042
A40: Physical Therapy, Evaluation | B40: 97161-97163 | C40: 553
...

Sheet CDM
A1: BillItemId | B1: BillItemLongDesc | C1: Charge
A2: 675856 | B2: BiPAP Management | C2: 0
A3: 675861 | B3: Bi-level Positive Airway Pressure | C3: 0
A4: 675862 | B4: Bi-level Positive Airway Pressure | C4: 0
A5: 758747 | B5: Local | C5: 0
A6: 758750 | B6: Regional Block | C6: 0
A7: 758754 | B7: General | C7: 0
A8: 758755 | B8: MAC | C8: 0
A9: 758757 | B9: Minor | C9: 0
A10: 884755 | B10: Moderate Sedation | C10: 0
A11: 958641 | B11: Alk Phos Isoenzyme LC | C11: 0
A12: 990676 | B12: ROOM/BED: Observation | C12: 0
A13: 1211602 | B13: .Gram Stain RLC | C13: 0
... A807: 50778191 | B807: Sodium Chloride 0.45% IV Sol 500 mL [CHA] | C807: 0
A808: 50792963 | B808: 81405 | C808: 0
A809: 50792964 | B809: 81406 | C809: 0
A810: 50792965 | B810: 82784 | C810: 0
A811: 50792966 | B811: 83516 | C811: 0
A812: 50792967 | B812: 83520 | C812: 0
A813: 50792968 | B813: 83883 | C813: 0
A814: 50792969 | B814: 86003 | C814: 0
A815: 50792970 | B815: 86008 | C815: 0
A816: 50792971 | B816: 86146 | C816: 0
A817: 50792972 | B817: 86147 | C817: 0
A818: 50792973 | B818: 86148 | C818: 0
A819: 50792974 | B819: 86160 | C819: 0
... A830: 50792985 | B830: 88185 | C830: 0
A831: 50866740 | B831: .6-Acetylmorphine Rescreen LC | C831: 0
A832: 50866742 | B832: .AMP/MAMP ReScreen, Urine LC | C832: 0
A833: 50866747 | B833: .Cocaine Metabolite ReScreen, U LC | C833: 0
A834: 50866749 | B834: .Codeine/Morphine Rescreen, Ur LC | C834: 0
A835: 50866754 | B835: .HYC/HYM ReScreen, Urine LC | C835: 0
A836: 50866758 | B836: .Opiates Conf Ur 799437 LC | C836: 0
A837: 50866760 | B837: .OXYC/OXYM ReScreen, Urine LC | C837: 0
A838: 50866762 | B838: .PCP Rescreen, Urine LC | C838: 0
A839: 50866765 | B839: .THCA ReScreen, Urine LC | C839: 0
A840: 50866768 | B840: Pap IG Aptima HPV,CtNg Age Gdln (Chart) LC | C840: 0
A841: 50878576 | B841: 80359 | C841: 0
A842: 50878577 | B842: 80361 | C842: 0
A843: 50878578 | B843: 82247 | C843: 0
...

Sheet Gross Revenue Percent Change
A1: Gross Revenue - 2023 Prices | B1: 5188679.7
A2: Gross Revenue - 2024 Prices | B2: 5442260.4
A3: Percent Change | B3: =+B2/B1-1 -> 0.048871904
A6: Methodology - see Sheet 3
A8: CDM comparison by two seprate periods

Sheet Sheet3
A1: BillItemId | B1: BillItemLongDesc | C1: 45444 | D1: 45107
A2: 49312618 | B2: ADHESIVE REMOVER WIPES | C2: =VLOOKUP(A2,CDM!$A$2:$C$14090,3,) -> 1 | D2: 1
A3: 49312661 | B3: PADS, TELFA (2"X3") | C3: =VLOOKUP(A3,CDM!$A$2:$C$14090,3,) -> 1 | D3: 1
A4: 49312662 | B4: PADS, TELFA (3"X4") 2132 | C4: =VLOOKUP(A4,CDM!$A$2:$C$14090,3,) -> 1 | D4: 1
A5: 49312668 | B5: 27G X 1-1/4 NEEDLE | C5: =VLOOKUP(A5,CDM!$A$2:$C$14090,3,) -> 1 | D5: 1
A6: 49312672 | B6: ADHESIVE DRESSING 1-1/2"X 3" | C6: =VLOOKUP(A6,CDM!$A$2:$C$14090,3,) -> 1 | D6: 1
A7: 49312699 | B7: PADS, ABDOMINAL 9190 | C7: =VLOOKUP(A7,CDM!$A$2:$C$14090,3,) -> 1 | D7: 1
A8: 49312708 | B8: KLEEN SPEC OTOSCOPE 2.5MM | C8: =VLOOKUP(A8,CDM!$A$2:$C$14090,3,) -> 1 | D8: 1
A9: 49312709 | B9: KLEENSPEC | C9: =VLOOKUP(A9,CDM!$A$2:$C$14090,3,) -> 1 | D9: 1
A10: 49312710 | B10: KLEENSPEC OTOSCOPE ADULT 4.25MM | C10: =VLOOKUP(A10,CDM!$A$2:$C$14090,3,) -> 1 | D10: 1
A11: 49312711 | B11: PILL CHUSHER POUCH | C11: =VLOOKUP(A11,CDM!$A$2:$C$14090,3,) -> 1 | D11: 1
A12: 49312565 | B12: PAD, EYE STERILE 50/BX | C12: =VLOOKUP(A12,CDM!$A$2:$C$14090,3,) -> 1 | D12: 1
A13: 49312706 | B13: DRESSING, TRACHEOTOMY DRAINAGE SPONGES | C13: =VLOOKUP(A13,CDM!$A$2:$C$14090,3,) -> 2 | D13: 2
... A3940: 48174600 | B3940: Cryoablation of Prostate | C3940: =VLOOKUP(A3940,CDM!$A$2:$C$14090,3,) -> 41887 | D3940: 39892
C3941: =SUM(C2:C3940) -> 5442260.4 | D3941: =SUM(D2:D3940) -> 5188679.7
A3944: Methodology - see Sheet 3
A3946: CDM comparison by two seprate periods, Jan 2023-Jun 2023 vs. Jan 2024-Jun 2024
A3947: Based on CDM activties in both periods, and average per charge for each CDM
