Workbook
Name qryECH_OSHPD_Annual_CDM_Prices: #REF!
Name qryECH_OSHPD_Annual_CDM_Prices: 'ECRMC PHARMACY AND IV CDM 2024'!$A$6:$K$6

Sheet Top 50 List
A1: Count | B1: Description | C1: Procedure Type
A2: 210 | B2: X-Ray, Chest, two views | C2: Radiology - X-Ray
A3: 201 | B3: Electrocardiogram | C3: Medicine - Cardiovascular
A4: 167 | B4: Comprehensive Metabolic Panel | C4: Laboratory
A5: 148 | B5: Complete Blood Count, with differential | C5: Laboratory
A6: 142 | B6: Basic Metabolic Panel | C6: Laboratory
A7: 134 | B7: X-Ray, Chest, one view | C7: Radiology - X-Ray
A8: 127 | B8: Prothrombin Time | C8: Laboratory
A9: 127 | B9: Physical Therapy - Therapeutic Exercise | C9: Medicine - Physical Medicine
A10: 121 | B10: Mammography, Screening, Bilateral | C10: Radiology
A11: 119 | B11: Colonoscopy | C11: Surgery
A12: 116 | B12: CT Scan, Head or Brain, without contrast | C12: Radiology - CT Scan
A13: 114 | B13: Urinalysis | C13: Laboratory
... A51: 34 | B51: Culture, Urine | C51: Laboratory

Sheet AB 1045 Form
A1: Hospital Name: El Centro Regional Medical Center
A2: HCAI Facility No: 103130699
A3: Effective Date of Charges: June 1, 2024
A5: In response to requests from hospitals and the public, HCAI has developed this form to assist hospitals in collecting and submitting the average charge for 25 common outpatient procedures performed by hospitals, as required by AB 1045 (Chapter 532, Statutes of 2005). Use of the HCAI form is voluntary, but highly encouraged, as it allows hospitals to report and the public to compare uniform information regarding common outpatient procedures.
A6: Evaluation & Management Services (CPT Codes 99201-99499) | B6: 2024 CPT Code | C6: Average Charge
A7: Emergency Room Visit (low to moderate severity) | B7: 99282 | C7: =+VLOOKUP(B7,CDM_FY24!F:I,4,0) -> 708
A8: Emergency Room Visit (moderate severity) | B8: 99283 | C8: =+VLOOKUP(B8,CDM_FY24!F:I,4,0) -> 1420
A9: Emergency Room Visit (high severity without signigicant threat) | B9: 99284 | C9: =+VLOOKUP(B9,CDM_FY24!F:I,4,0) -> 2250
A10: Emergency Room Visit (high severity with significant threat) | B10: 99285 | C10: =+VLOOKUP(B10,CDM_FY24!F:I,4,0) -> 3425
A11: Outpatient Visit, established patient, 15 minutes | B11: 99213
A12: Laboratory & Pathology Services (CPT Codes 80047-89398) | B12: 2024 CPT Code | C12: Average Charge
A13: Basic Metabolic Panel | B13: 80048 | C13: =+VLOOKUP(B13,CDM_FY24!F:I,4,0) -> 307
A14: Blood Gas Analysis, including 02 saturation | B14: 82805 | C14: =+VLOOKUP(B14,CDM_FY24!F:I,4,0) -> 926
A15: Complete Blood Count, automated | B15: 85027 | C15: =+VLOOKUP(B15,CDM_FY24!F:I,4,0) -> 128
A16: Complete Blood Count, with differential WBC, automated | B16: 85025 | C16: =+VLOOKUP(B16,CDM_FY24!F:I,4,0) -> 150
A17: Comprehensive Metabolic Panel | B17: 80053 | C17: =+VLOOKUP(B17,CDM_FY24!F:I,4,0) -> 370
A18: Creatine Kinase (CK), (CPK), Total | B18: 82550
A19: Lipid Panel | B19: 80061
A20: Partial Thromboplastin Time | B20: 85730
A21: Prothrombin Time | B21: 85610
A22: Thyroid Stimulating Hormone | B22: 84443
A23: Troponin, Quantitative | B23: 84484 | C23: =+VLOOKUP(B23,CDM_FY24!F:I,4,0) -> 295
A24: Urinalysis, without microscopy | B24: 81002 | C24: =+VLOOKUP(B24,CDM_FY24!F:I,4,0) -> 36
A25: Urinalysis, with microscopy | B25: 81000 | C25: =+VLOOKUP(B25,CDM_FY24!F:I,4,0) -> 227
A26: Radiology Services (CPT Codes 70010-79999) | B26: 2024 CPT Code | C26: Average Charge
A27: CT Scan, Abdomen, with contrast | B27: 74160 | C27: =+VLOOKUP(B27,CDM_FY24!F:I,4,0) -> 4091
A28: CT Scan, Head or Brain, without contrast | B28: 70450 | C28: =+VLOOKUP(B28,CDM_FY24!F:I,4,0) -> 3810
A29: CT Scan, Pelvis, with contrast | B29: 72193 | C29: =+VLOOKUP(B29,CDM_FY24!F:I,4,0) -> 3719
A30: Mammography, Screening, Bilateral | B30: 77067 | C30: =+VLOOKUP(B30,CDM_FY24!F:I,4,0) -> 455
A31: MRI, Brain, without contrast, followed by contrast | B31: 70553 | C31: =+VLOOKUP(B31,CDM_FY24!F:I,4,0) -> 6949
A32: Ultrasound, Abdomen, Complete | B32: 76700
A33: Ultrasound, OB, 14 weeks or more, transabdominal | B33: 76805 | C33: =+VLOOKUP(B33,CDM_FY24!F:I,4,0) -> 1127
A34: X-Ray, Lower Back, minimum four views | B34: 72110 | C34: =+VLOOKUP(B34,CDM_FY24!F:I,4,0) -> 1102
A35: X-Ray, Chest, two views | B35: 71046 | C35: =+VLOOKUP(B35,CDM_FY24!F:I,4,0) -> 625
A36: Medicine Services (CPT Codes 90281-99607) | B36: 2024 CPT Code | C36: Average Charge
A37: Cardiac Catheterization, Left Heart, percutaneous | B37: 93452
A38: Echocardiography, Transthoracic, complete, without Doppler | B38: 93307 | C38: =+VLOOKUP(B38,CDM_FY24!F:I,4,0) -> 1898
A39: Electrocardiogram, routine, with interpretation and report | B39: 93000 | C39: =+VLOOKUP(B39,CDM_FY24!F:I,4,0) -> 333.03
A40: Inhalation Treatment, pressurized or nonpressurized | B40: 94640
A41: Physical Therapy, Evaluation | B41: 97161 | C41: =+VLOOKUP(B41,CDM_FY24!F:I,4,0) -> 354
...

Sheet ECRMC 2024 CDM
A1: EL CENTRO REGIONAL MEDICAL CENTER
A2: HCAI FACILITY NO. 106130699
A3: CHARGEMASTER LIST EXCLUDING DRUGS SOLD TO PATIENTS AND IV'S SOLD TO PATIENTS- LISTED SEPARATELY
A4: 45444
A7: CDM# | B7: CDM DESC | C7: PRICE
A8: 0000200 | B8: R/B MEDICAL/SURG EAST & WEST | C8: 2357
A9: 0000300 | B9: R/B MED SURG TELEMETRY E/W | C9: 2970
A10: 0000400 | B10: R/B MED SURG TELE & ISOL E/W | C10: 4279
A11: 0000600 | B11: R/B MED SURG ISOLATION E/W | C11: 2970
A12: 0000900 | B12: R/B MEDICAL/SURG NORTH & SOUTH | C12: 2357
A13: 0000900 | B13: R/B MEDICAL/SURG NORTH & SOUTH | C13: 0
A14: 0000901 | B14: R/B MED SURG TELEMETRY N/S | C14: 2970
A15: 0000902 | B15: R/B MED SURG TELE&ISOL N/S | C15: 4279
A16: 0000903 | B16: R/B MED SURG ISOLATION N/S | C16: 2970
A17: 0001000 | B17: R/B ICU | C17: 6031
A18: 0001000 | B18: R/B ICU | C18: 0
A19: 0001100 | B19: R/B ICU ISOLATION | C19: 6393
... A2709: 7392001 | B2709: TELEHEALTH FACILITY FEE CDCR | C2709: 83

Sheet ECRMC PHARMACY AND IV CDM 2024
A1: EL CENTRO REGIONAL MEDICAL CENTER
A2: OSHPD FACILITY NO. 106130699
A3: CHARGEMASTER FOR DRUGS SOLD TO PATIENTS AND INTRAVENOUS SOLUTIONS
A4: 45489
A6: CDM CODE | B6: BRAND_NAME | C6: GENERIC_NAME | D6: AVERAGE WHOLESALE PRICE (AWP) | E6: % MARK-UP | F6: IV_PVAR1_DPU | G6: DISP_DESCR_CDM | H6: DPD_IND | I6: INH_UNIT_COST_DPD | J6: MED_PVAR1_DPD | K6: IV_PVAR1_DPD
A7: 3210301 | B7: NACL 0.45% | C7: NACL 0.45% 1000ML IV BAG | D7: 7.98 | E7: 7.22
A8: 3210303 | B8: NACL 0.9% | C8: NACL 0.9% 250ML IV BAG | D8: 6.44 | E8: 7.22
A9: 3210303 | B9: -NACL 0.9% | C9: NACL 0.9% 250ML IV BAG | D9: 6.44 | E9: 7.22
A10: 3210304 | B10: NACL 0.9% | C10: NACL 0.9% 1000ML IV BAG | D10: 6.97 | E10: 7.22
A11: 3210305 | B11: NACL 3% HYPERTONIC | C11: NACL 3% IV 500ML | D11: 6.91 | E11: 7.22
A12: 3210306 | B12: VITAMIN A&D OINT | C12: VITAMIN A & D OINTMENT | D12: 0.18 | E12: 7.22
A13: 3210315 | B13: ACTIVATED CHARCOAL | C13: ACTIDOSE-AQUA 50 GM LIQUID | D13: 23.65 | E13: 7.22
A14: 3210316 | B14: CHARCOAL/SORBITOL SOLUTION | C14: ACTIDOSE 25 GM LIQUID | D14: 16.70 | E14: 7.22
A15: 3210317 | B15: CHARCOAL/SORBITOL SOLUTION | C15: ACTIDOSE 50 GM LIQUID | D15: 23.65 | E15: 7.22
A16: 3210319 | B16: ALTEPLASE | C16: ACTIVASE 100 MG VIAL | D16: 5218.49 | E16: 4.17
A17: 3210321 | B17: PIOGLITAZONE | C17: ACTOS 15 MG TABLET | D17: 5.78 | E17: 7.22
A18: 3210323 | B18: KETOROLAC TROMETHAMINE 0.5% | C18: ACULAR 0.5% EYE DROPS 5ML | D18: 125.99 | E18: 7.22
... A1818: 3213484 | B1818: TREMELIMUMAB-ACTL | C1818: IMJUDO 300 MG/15 ML VIAL | D1818: 39780.00 | E1818: 3.18

Sheet Gross Revenue Difference
A1: EL CENTRO REGIONAL MEDICAL CENTER
A2: HCAI FACILITY NO. 106130699
A3: Calculation of Percent Change in Gross Revenue
A4: Reporting Period June 1, 2024
B8: Gross Patient Revenue
B9: YTD
A11: 45078 | B11: 6.6182231e+08 | C11: (a)
A13: 45444 | B13: 6.4509606e+08 | C13: (a)
A15: Decrease in Revenue due to changes in utilization, new and/or discontinued services.
B16: =B13-B11 -> -16726256
A18: Increase as % of Gross Patient Revenue | B18: =B16/B11 -> -0.025273032
A22: El Centro Regional Medical Center did not pursue a pricing adjustment as of last year's submission and as such has no substantive variance in gross charges related to price changes.
A25: U:\2024\11 - May\RAT_PROSHEET_0524 - Period 11 FY2024.xlsx | C25: (a)

Sheet CDM_FY24
A2: Dpt# | B2: Dept Name | C2: Pat Type | D2: Charge Cd | E2: Charge Desc | F2: CPT CODE | G2: MTD Usage | H2: MTD Revenue | I2: Avg Price
A3: 3170 | B3: MEDICAL/SURGICAL EAST & WEST | C3: INPATIENT | D3: 0000200 | E3: R/B MEDICAL/SURG EAST & WEST | F3: 0 | G3: 5777 | H3: 13616389 | I3: =IFERROR(H3/G3,0) -> 2357
A4: 3170 | B4: MEDICAL/SURGICAL EAST & WEST | C4: OUTPATIENT | D4: 0000200 | E4: R/B MEDICAL/SURG EAST & WEST | F4: 0 | G4: 1 | H4: 2357 | I4: =IFERROR(H4/G4,0) -> 2357
A5: 3170 | B5: MEDICAL/SURGICAL EAST & WEST | C5: INPATIENT | D5: 0000300 | E5: R/B MED SURG TELEMETRY E/W | F5: 0 | G5: 4630 | H5: 13751100 | I5: =IFERROR(H5/G5,0) -> 2970
A6: 3170 | B6: MEDICAL/SURGICAL EAST & WEST | C6: OUTPATIENT | D6: 0000300 | E6: R/B MED SURG TELEMETRY E/W | F6: 0 | G6: 3 | H6: 8910 | I6: =IFERROR(H6/G6,0) -> 2970
A7: 3170 | B7: MEDICAL/SURGICAL EAST & WEST | C7: INPATIENT | D7: 0000400 | E7: R/B MED SURG TELE & ISOL E/W | F7: 0 | G7: 848 | H7: 3628592 | I7: =IFERROR(H7/G7,0) -> 4279
A8: 3170 | B8: MEDICAL/SURGICAL EAST & WEST | C8: INPATIENT | D8: 0000600 | E8: R/B MED SURG ISOLATION E/W | F8: 0 | G8: 1208 | H8: 3587760 | I8: =IFERROR(H8/G8,0) -> 2970
A9: 3170 | B9: MEDICAL/SURGICAL EAST & WEST | C9: INPATIENT | D9: 0000900 | E9: R/B MEDICAL/SURG NORTH & SOUTH | F9: 0 | G9: 1501 | H9: 3537857 | I9: =IFERROR(H9/G9,0) -> 2357
A10: 3170 | B10: MEDICAL/SURGICAL EAST & WEST | C10: OUTPATIENT | D10: 0000900 | E10: R/B MEDICAL/SURG NORTH & SOUTH | F10: 0 | G10: 0 | H10: 0 | I10: =IFERROR(H10/G10,0) -> 0
A11: 3170 | B11: MEDICAL/SURGICAL EAST & WEST | C11: INPATIENT | D11: 0000901 | E11: R/B MED SURG TELEMETRY N/S | F11: 0 | G11: 566 | H11: 1681020 | I11: =IFERROR(H11/G11,0) -> 2970
A12: 3170 | B12: MEDICAL/SURGICAL EAST & WEST | C12: INPATIENT | D12: 0000902 | E12: R/B MED SURG TELE&ISOL N/S | F12: 0 | G12: 65 | H12: 278135 | I12: =IFERROR(H12/G12,0) -> 4279
A13: 3170 | B13: MEDICAL/SURGICAL EAST & WEST | C13: INPATIENT | D13: 0000903 | E13: R/B MED SURG ISOLATION N/S | F13: 0 | G13: 145 | H13: 430650 | I13: =IFERROR(H13/G13,0) -> 2970
A14: 3010 | B14: ICU | C14: INPATIENT | D14: 0001000 | E14: R/B ICU | F14: 0 | G14: 1009 | H14: 6085279 | I14: =IFERROR(H14/G14,0) -> 6031
... A21: 3290 | B21: PEDIATRICS | C21: INPATIENT | D21: 0004200 | E21: R/B PEDIATRICS | F21: 0 | G21: 0 | H21: 0 | I21: =IFERROR(H21/G21,0) -> 0
A22: 8721 | B22: POPULATION HEALTH | C22: OUTPATIENT | D22: 110100 | E22: ECM IN-PERSON: PROVIDED BY CLINICAL STAFF | F22: G9008 | G22: 23 | H22: 9200 | I22: =IFERROR(H22/G22,0) -> 400
A23: 8721 | B23: POPULATION HEALTH | C23: OUTPATIENT | D23: 110101 | E23: ECM PHONE/TELEHEALTH:PROVIDED BY CLINICAL STAFF | F23: G9008 | G23: 336 | H23: 134400 | I23: =IFERROR(H23/G23,0) -> 400
A24: 8721 | B24: POPULATION HEALTH | C24: OUTPATIENT | D24: 110102 | E24: ECM IN-PERSON: PROVIDED BY NON-CLINICAL STAFF | F24: G9012 | G24: 19 | H24: 7600 | I24: =IFERROR(H24/G24,0) -> 400
A25: 8721 | B25: POPULATION HEALTH | C25: OUTPATIENT | D25: 110103 | E25: ECM PHONE/TELEHEALTH:PROVIDED NON-CLINICAL STAFF | F25: G9012 | G25: 471 | H25: 188400 | I25: =IFERROR(H25/G25,0) -> 400
A26: 8721 | B26: POPULATION HEALTH | C26: OUTPATIENT | D26: 110104 | E26: ECM OUTREACH | F26: G9012 | G26: 1847 | H26: 738800 | I26: =IFERROR(H26/G26,0) -> 400
A27: 8721 | B27: POPULATION HEALTH | C27: OUTPATIENT | D27: 110105 | E27: SUD SELF-MANAGEMENT EDUCATION 30 MIN FACE-FACE | F27: 98960 | G27: 178 | H27: 11863.7 | I27: =IFERROR(H27/G27,0) -> 66.65
A28: 4010 | B28: EMERGENCY ROOM | C28: INPATIENT | D28: 1000000 | E28: CLASS 5 EMERGENCY ROOM VISIT | F28: 99285 | G28: 2847 | H28: 9750975 | I28: =IFERROR(H28/G28,0) -> 3425
A29: 4010 | B29: EMERGENCY ROOM | C29: OUTPATIENT | D29: 1000000 | E29: CLASS 5 EMERGENCY ROOM VISIT | F29: 99285 | G29: 2954 | H29: 10117450 | I29: =IFERROR(H29/G29,0) -> 3425
A30: 4010 | B30: EMERGENCY ROOM | C30: INPATIENT | D30: 1000100 | E30: CLASS 4 EMERGENCY ROOM VISIT | F30: 99284 | G30: 9 | H30: 20250 | I30: =IFERROR(H30/G30,0) -> 2250
A31: 4010 | B31: EMERGENCY ROOM | C31: OUTPATIENT | D31: 1000100 | E31: CLASS 4 EMERGENCY ROOM VISIT | F31: 99284 | G31: 11555 | H31: 25998750 | I31: =IFERROR(H31/G31,0) -> 2250
A32: 4010 | B32: EMERGENCY ROOM | C32: INPATIENT | D32: 1000200 | E32: CLASS 3 EMERGENCY ROOM VISIT | F32: 99283 | G32: 3 | H32: 4260 | I32: =IFERROR(H32/G32,0) -> 1420
A33: 4010 | B33: EMERGENCY ROOM | C33: OUTPATIENT | D33: 1000200 | E33: CLASS 3 EMERGENCY ROOM VISIT | F33: 99283 | G33: 13427 | H33: 19066340 | I33: =IFERROR(H33/G33,0) -> 1420
A34: 4010 | B34: EMERGENCY ROOM | C34: INPATIENT | D34: 1000300 | E34: CLASS 2 EMERGENCY ROOM VISIT | F34: 99282 | G34: 1 | H34: 708 | I34: =IFERROR(H34/G34,0) -> 708
A35: 4010 | B35: EMERGENCY ROOM | C35: OUTPATIENT | D35: 1000300 | E35: CLASS 2 EMERGENCY ROOM VISIT | F35: 99282 | G35: 1887 | H35: 1335996 | I35: =IFERROR(H35/G35,0) -> 708
A36: 4010 | B36: EMERGENCY ROOM | C36: OUTPATIENT | D36: 1000400 | E36: CLASS 1 EMERGENCY ROOM VISIT | F36: 99281 | G36: 1044 | H36: 316332 | I36: =IFERROR(H36/G36,0) -> 303
A37: 4010 | B37: EMERGENCY ROOM | C37: OUTPATIENT | D37: 1000402 | E37: MEDHOST E&M 1 99281 STATISTIC | F37: 0 | G37: 1539 | H37: 0 | I37: =IFERROR(H37/G37,0) -> 0
A38: 4010 | B38: EMERGENCY ROOM | C38: INPATIENT | D38: 1000403 | E38: MEDHOST E&M 2 99282 STATISTIC | F38: 0 | G38: 1 | H38: 0 | I38: =IFERROR(H38/G38,0) -> 0
... A55: 4010 | B55: EMERGENCY ROOM | C55: OUTPATIENT | D55: 1001001 | E55: CRITICAL CARE EACH ADD 30 MIN | F55: 99292 | G55: 60 | H55: 138360 | I55: =IFERROR(H55/G55,0) -> 2306
A56: 4010 | B56: EMERGENCY ROOM | C56: INPATIENT | D56: 1001002 | E56: TRAUMA CODE ACTIVATION | F56: G0390 | G56: 2 | H56: 12520 | I56: =IFERROR(H56/G56,0) -> 6260
A57: 4010 | B57: EMERGENCY ROOM | C57: OUTPATIENT | D57: 1001002 | E57: TRAUMA CODE ACTIVATION | F57: G0390 | G57: 27 | H57: 169020 | I57: =IFERROR(H57/G57,0) -> 6260
A58: 4470 | B58: MEDICAL SUPPLIES SOLD TO PATIENTS | C58: INPATIENT | D58: 1001300 | E58: OXYGEN | F58: 0 | G58: 154 | H58: 8932 | I58: =IFERROR(H58/G58,0) -> 58
A59: 4470 | B59: MEDICAL SUPPLIES SOLD TO PATIENTS | C59: OUTPATIENT | D59: 1001300 | E59: OXYGEN | F59: 0 | G59: 212 | H59: 12296 | I59: =IFERROR(H59/G59,0) -> 58
A60: 4010 | B60: EMERGENCY ROOM | C60: INPATIENT | D60: 1001901 | E60: ER NON CHARGEABLE SUPPLIES,NCH | F60: 0 | G60: 164 | H60: 0 | I60: =IFERROR(H60/G60,0) -> 0
A61: 4010 | B61: EMERGENCY ROOM | C61: OUTPATIENT | D61: 1001901 | E61: ER NON CHARGEABLE SUPPLIES,NCH | F61: 0 | G61: 322 | H61: 0 | I61: =IFERROR(H61/G61,0) -> 0
A62: 4010 | B62: EMERGENCY ROOM | C62: INPATIENT | D62: 1001902 | E62: ER NO CHG. LAB CHG. | F62: 0 | G62: 435 | H62: 0 | I62: =IFERROR(H62/G62,0) -> 0
A63: 4010 | B63: EMERGENCY ROOM | C63: OUTPATIENT | D63: 1001902 | E63: ER NO CHG. LAB CHG. | F63: 0 | G63: 1487 | H63: 0 | I63: =IFERROR(H63/G63,0) -> 0
...

Sheet Sheet1
A2: DEPT# | B2: DEPT NAME | C2: CDM# | D2: CDM DESC | E2: CDM BILLING DESC | F2: TOTAL COST | G2: PRICE | H2: EFF DT | I2: DEFAULT CPT | J2: DEFAULT CPT MOD | K2: MCARE OVR CPT | L2: MCARE OVR MOD | M2: MCAL OVR CPT | N2: MCAL OVR MOD | O2: DEFAULT REV CD | P2: MCARE OVR REV CD | Q2: MCAL OVR REV CD | R2: Y ECRMC - CHARGE CODE LIST (FILE)
A3: 3170 | B3: MEDICAL/SURGICAL EAST & WEST | C3: 0000200 | D3: R/B MEDICAL/SURG EAST & WEST | E3: R/B - MED SURG SEMI-PRIVATE EAST & WEST | F3: **N/A** | G3: 2357 | H3: 41091 | O3: 120 | Q3: 121
A4: 3170 | B4: MEDICAL/SURGICAL EAST & WEST | C4: 0000300 | D4: R/B MED SURG TELEMETRY E/W | E4: R/B - MED SURG TELEMETRY EAST & WEST | F4: **N/A** | G4: 2970 | H4: 41091 | O4: 120 | Q4: 121
A5: 3170 | B5: MEDICAL/SURGICAL EAST & WEST | C5: 0000400 | D5: R/B MED SURG TELE & ISOL E/W | E5: R/B - MED SURG TELEMETRY & ISOLATION EAST & WEST | F5: **N/A** | G5: 4279 | H5: 41091 | O5: 164 | Q5: 111
A6: 3170 | B6: MEDICAL/SURGICAL EAST & WEST | C6: 0000600 | D6: R/B MED SURG ISOLATION E/W | E6: R/B MED SURG ISOLATION EAST & WEST | F6: **N/A** | G6: 2970 | H6: 41091 | O6: 164 | Q6: 111
A7: 3170 | B7: MEDICAL/SURGICAL EAST & WEST | C7: 0000900 | D7: R/B MEDICAL/SURG NORTH & SOUTH | E7: R/B MEDICAL/SURGICAL SEMI-PRIVATE NORTH & SOUTH | F7: **N/A** | G7: 2357 | H7: 41456 | O7: 120 | Q7: 121
A8: 3170 | B8: MEDICAL/SURGICAL EAST & WEST | C8: 0000901 | D8: R/B MED SURG TELEMETRY N/S | E8: R/B MED SURG TELEMETRY NORTH & SOUTH | F8: **N/A** | G8: 2970 | H8: 41456 | O8: 120 | Q8: 121
A9: 3170 | B9: MEDICAL/SURGICAL EAST & WEST | C9: 0000902 | D9: R/B MED SURG TELE&ISOL N/S | E9: R/B MED SURG TELEMETRY & ISOLATION NORTH & SOUTH | F9: **N/A** | G9: 4279 | H9: 41456 | O9: 164 | Q9: 111
A10: 3170 | B10: MEDICAL/SURGICAL EAST & WEST | C10: 0000903 | D10: R/B MED SURG ISOLATION N/S | E10: R/B MED SURG ISOLATION NORTH & SOUTH | F10: **N/A** | G10: 2970 | H10: 41456 | O10: 164 | Q10: 111
A11: 3010 | B11: ICU | C11: 0001000 | D11: R/B ICU | E11: R/B ICU | F11: **N/A** | G11: 6031 | H11: 41091 | O11: 200
A12: 3010 | B12: ICU | C12: 0001100 | D12: R/B ICU ISOLATION | E12: R/B ICU ISOLATION | F12: **N/A** | G12: 6393 | H12: 41091 | O12: 200
A13: 3150 | B13: DEFINITIVE OBSERVATION UNIT | C13: 0001200 | D13: R/B DOU ISOLATION | E13: R/B DOU ISOLATION | F13: **N/A** | G13: 4478 | H13: 41149 | O13: 110 | Q13: 206
A14: 3150 | B14: DEFINITIVE OBSERVATION UNIT | C14: 0001300 | D14: R/B DOU | E14: R/B DOU | F14: **N/A** | G14: 3999 | H14: 41149 | O14: 110 | Q14: 206
A15: 3380 | B15: OBSTETRICS | C15: 0002200 | D15: R/B OB | E15: R/B OB | F15: **N/A** | G15: 2631 | H15: 41149 | O15: 122
A16: 3380 | B16: OBSTETRICS | C16: 0002600 | D16: R/B OB ISOLATION | E16: R/B OB ISOLATION | F16: **N/A** | G16: 3622 | H16: 41149 | O16: 164 | Q16: 112
A17: 3530 | B17: NURSERY | C17: 0003000 | D17: R/B NEWBORN I NORMAL NEWBORN | E17: R/B NEWBORN I NORMAL NEWBORN | F17: **N/A** | G17: 1653 | H17: 41091 | O17: 171
A18: 3530 | B18: NURSERY | C18: 0003100 | D18: R/B NEWBORN II CONTINUING CARE | E18: R/B NEWBORN II CONTINUING CARE | F18: **N/A** | G18: 2269 | H18: 42186 | O18: 172
A19: 3530 | B19: NURSERY | C19: 0003300 | D19: R/B NEWBORN III INTERMEDIATE | E19: R/B NEWBORN III INTERMEDIATE CARE | F19: **N/A** | G19: 3693 | H19: 41149 | O19: 173
A20: 3290 | B20: PEDIATRICS | C20: 0004200 | D20: R/B PEDIATRICS | E20: R/B PEDS SEMI-PRIVATE | F20: **N/A** | G20: 2378 | H20: 41091 | O20: 123
A21: 3290 | B21: PEDIATRICS | C21: 0004600 | D21: R/B PEDS ISOLATION | E21: R/B PEDS ISOLATION | F21: **N/A** | G21: 2970 | H21: 41091 | O21: 164 | Q21: 113
A22: 4010 | B22: EMERGENCY ROOM | C22: 1000000 | D22: CLASS 5 EMERGENCY ROOM VISIT | E22: CLASS 5 EMERGENCY ROOM VISIT | F22: **N/A** | G22: 3425 | H22: 44197 | I22: 99285 | J22: 25 | M22: Z7502 | O22: 450
A23: 4010 | B23: EMERGENCY ROOM | C23: 1000100 | D23: CLASS 4 EMERGENCY ROOM VISIT | E23: CLASS IV EXTENSIVE | F23: **N/A** | G23: 2250 | H23: 44197 | I23: 99284 | J23: 25 | M23: Z7502 | O23: 450
A24: 4010 | B24: EMERGENCY ROOM | C24: 1000200 | D24: CLASS 3 EMERGENCY ROOM VISIT | E24: CLASS III MODERATE | F24: **N/A** | G24: 1420 | H24: 44197 | I24: 99283 | J24: 25 | M24: Z7502 | O24: 450
A25: 4010 | B25: EMERGENCY ROOM | C25: 1000300 | D25: CLASS 2 EMERGENCY ROOM VISIT | E25: CLASS II ROUTINE | F25: **N/A** | G25: 708 | H25: 44197 | I25: 99282 | J25: 25 | M25: Z7502 | O25: 450
A26: 4010 | B26: EMERGENCY ROOM | C26: 1000400 | D26: CLASS 1 EMERGENCY ROOM VISIT | E26: CLASS 1 EMERGENCY ROOM VISIT | F26: **N/A** | G26: 303 | H26: 44197 | I26: 99281 | J26: 25 | M26: Z7502 | O26: 450
A27: 4010 | B27: EMERGENCY ROOM | C27: 1000401 | D27: MEDHOST E&M LEVEL STATISTIC | E27: MEDHOST E&M LEVEL STATISTIC | F27: **N/A** | G27: 0 | H27: 42552 | O27: 450
A28: 4010 | B28: EMERGENCY ROOM | C28: 1000402 | D28: MEDHOST E&M 1 99281 STATISTIC | E28: MEDHOST E&M 1 99281 STATISTIC | F28: **N/A** | G28: 0 | H28: 42552 | O28: 450
A29: 4010 | B29: EMERGENCY ROOM | C29: 1000403 | D29: MEDHOST E&M 2 99282 STATISTIC | E29: MEDHOST E&M 2 99282 STATISTIC | F29: **N/A** | G29: 0 | H29: 42552 | O29: 450
A30: 4010 | B30: EMERGENCY ROOM | C30: 1000404 | D30: MEDHOST E&M 3 99283 STATISTIC | E30: MEDHOST E&M 3 99283 STATISTIC | F30: **N/A** | G30: 0 | H30: 42552 | O30: 450
A31: 4010 | B31: EMERGENCY ROOM | C31: 1000405 | D31: MEDHOST E&M 4 99284 STATISTIC | E31: MEDHOST E&M 4 99284 STATISTIC | F31: **N/A** | G31: 0 | H31: 42552 | O31: 450
A32: 4010 | B32: EMERGENCY ROOM | C32: 1000406 | D32: MEDHOST E&M 5 99285 STATISTIC | E32: MEDHOST E&M 5 99285 STATISTIC | F32: **N/A** | G32: 0 | H32: 42552 | O32: 450
A33: 4010 | B33: EMERGENCY ROOM | C33: 1000407 | D33: MEDHOST E&M 6 99291 STATISTIC | E33: MEDHOST E&M 6 99291 STATISTIC | F33: **N/A** | G33: 0 | H33: 42552 | O33: 450
A34: 4010 | B34: EMERGENCY ROOM | C34: 1000408 | D34: MEDHOST E&M 7 99292 STATISTIC | E34: MEDHOST E&M 7 99292 STATISTIC | F34: **N/A** | G34: 0 | H34: 42552 | O34: 450
A35: 4010 | B35: EMERGENCY ROOM | C35: 1000800 | D35: EMPLOYEE HEALTH | E35: EMPLOYEE HEALTH | F35: **N/A** | G35: 61 | H35: 42917 | O35: 450
A36: 4010 | B36: EMERGENCY ROOM | C36: 1000900 | D36: ER VISIT NO CHARGE. ELOPEMENT | E36: ER VISIT NO CHARGE. ELOPEMENT | F36: **N/A** | G36: 0 | H36: 42552 | O36: 450
A37: 4010 | B37: EMERGENCY ROOM | C37: 1001000 | D37: CLASS 6 CRITICAL CARE 30-74MIN | E37: CLASS 6 CRITICAL CARE 30-74 MINUTES | F37: **N/A** | G37: 5927 | H37: 44197 | I37: 99291 | J37: 25 | M37: Z7502 | O37: 450
A38: 4010 | B38: EMERGENCY ROOM | C38: 1001001 | D38: CRITICAL CARE EACH ADD 30 MIN | E38: CRITICAL CARE EACH ADD 30 MIN | F38: **N/A** | G38: 2306 | H38: 44197 | I38: 99292 | J38: 25 | M38: Z7502 | O38: 450
A39: 4010 | B39: EMERGENCY ROOM | C39: 1001002 | D39: TRAUMA CODE ACTIVATION | E39: TRAUMA CODE ACTIVATION | F39: **N/A** | G39: 6260 | H39: 44197 | I39: G0390 | O39: 684 | Q39: 450
A40: 4470 | B40: MEDICAL SUPPLIES SOLD TO PATIENTS | C40: 1001300 | D40: OXYGEN | E40: OXYGEN | F40: **N/A** | G40: 58 | H40: 42553 | M40: Z7610 | O40: 270
A41: 4391 | B41: OUTPATIENT TREATMENT CENTER | C41: 1001701 | D41: IV INF ADD HR THER/PROF/DIAG | E41: IV INF ADD HR THER/PROF/DIAG | F41: **N/A** | G41: 254 | H41: 44197 | I41: 96366 | M41: 96366 | O41: 260
...
